<?xml version="1.0"?>
<robot name="rightHand">
  <link name="wristLarge">
    <visual>
      <geometry>
        <mesh filename="package://inmoov_urdf/meshes/rightHand/WristlargeV4.stl" scale=".001 .001 .001"/>
      </geometry>
      <material name="creme">
        <color rgba="255 253 208 1"/>
      </material>
    </visual>
  </link>

  <link name="wristPinky">
    <visual>
      <geometry>
        <mesh filename="package://inmoov_urdf/meshes/rightHand/wristSmallPinky.stl" scale=".001 .001 .001"/>
      </geometry>
      <material name="creme"/>
      <origin rpy="0 0 -0.90" xyz="-0.01 0.0115 -0.0102"/>
    </visual>
  </link>

  <joint name="pinkyKnuck1" type="revolute">
    <limit upper="0.3" lower="0.0" effort="1000.0" velocity="0.5"/>
    <origin rpy="0 0 4.03171057" xyz="0.005 -0.0105 .0105"/>
    <parent link="wristLarge"/>
    <child link="wristPinky"/>
  </joint>

  <link name="wristRing">
    <visual>
      <geometry>
        <mesh filename="package://inmoov_urdf/meshes/rightHand/wristSmallRing.stl" scale=".001 .001 .001"/>
      </geometry>
      <origin rpy="0 0 -0.90" xyz="-0.01 0.0115 -0.0102"/>
      <material name="creme"/>
    </visual>
  </link>

  <joint name="ringKnuck1" type="revolute">
    <limit upper="0.23" lower="0.0" effort="1000.0" velocity="0.5"/>
    <origin rpy="0 0 4.03171057" xyz="0.005 -0.0105 0.0105"/>
    <parent link="wristLarge"/>
    <child link="wristRing"/>
  </joint>

  <link name="indexSeg6">
    <visual>
      <geometry>
        <mesh filename="package://inmoov_urdf/meshes/rightHand/indexSeg6.stl" scale=".001 .001 .001"/>
      </geometry>
      <origin rpy="-1.570796 0 0" xyz="0.01 -0.0207 0.0008"/>
      <material name="creme"/>
    </visual>
  </link>

  <joint name="indexKnuck1" type="revolute">
    <limit upper="-1.74533" lower="0.0" effort="1000.0" velocity="0.5"/>
    <origin rpy="0 0 -0.0875" xyz="-0.0352 -0.0505 0.0107"/>
    <parent link="wristLarge"/>
    <child link="indexSeg6"/>
  </joint>

  <link name="indexSeg5">
    <visual>
      <geometry>
        <mesh filename="package://inmoov_urdf/meshes/rightHand/indexSeg5.stl" scale=".001 .001 .001"/>
      </geometry>
      <origin rpy="1.57 0 0" xyz="-0.0119 -0.0207 0.0012"/>
      <material name="creme"/>
    </visual>
  </link>

  <joint name="indexKnuck1.5" type="fixed">
    <parent link="indexSeg6"/>
    <child link="indexSeg5"/>
  </joint>

  <link name="indexSeg4">
    <visual>
      <geometry>
        <mesh filename="package://inmoov_urdf/meshes/rightHand/indexSeg4.stl" scale=".001 .001 .001"/>
      </geometry>
      <origin rpy="1.57 0 3.14" xyz="-0.0119 -0.0118 -0.0282"/>
      <material name="creme"/>
    </visual>
  </link>

  <joint name="indexKnuck2" type="revolute">
    <limit upper="-1.4" lower="0.0" effort="1000.0" velocity="0.5"/>
    <origin rpy="0 0 0" xyz="-0.0011 -0.0362 0.0007"/>
    <parent link="indexSeg5"/>
    <child link="indexSeg4"/>
  </joint>

  <link name="indexSeg3">
    <visual>
      <geometry>
        <mesh filename="package://inmoov_urdf/meshes/rightHand/indexSeg3.stl" scale=".001 .001 .001"/>
      </geometry>
      <origin rpy="-1.57 0 3.14" xyz="0.0112 -0.0118 0.0274"/>
      <material name="creme"/>
    </visual>
  </link>

  <joint name="indexKnuck2.5" type="fixed">
    <parent link="indexSeg4"/>
    <child link="indexSeg3"/>
  </joint>

  <link name="indexSeg2">
    <visual>
      <geometry>
        <mesh filename="package://inmoov_urdf/meshes/rightHand/indexSeg2.stl" scale=".001 .001 .001"/>
      </geometry>
      <origin rpy="1.57 0 3.14" xyz="-0.0119 -0.01345 0.02695"/>
      <material name="creme"/>
    </visual>
  </link>

  <joint name="indexKnuck3" type="revolute">
    <limit upper="-0.87" lower="0.0" effort="1000.0" velocity="0.5"/>
    <origin rpy="0 0 0" xyz="-0.00035 -0.02408 -0.00042"/>
    <parent link="indexSeg3"/>
    <child link="indexSeg2"/>
  </joint>

  <link name="indexSeg1">
    <visual>
      <geometry>
        <mesh filename="package://inmoov_urdf/meshes/rightHand/indexSeg1.stl" scale=".001 .001 .001"/>
      </geometry>
      <origin rpy="-1.57 0 3.14" xyz="0.01203 -0.0135 -0.02565"/>
      <material name="creme"/>
    </visual>
  </link>

  <joint name="indexKnuck3.5" type="fixed">
    <parent link="indexSeg2"/>
    <child link="indexSeg1"/>
  </joint>
</robot>
