<?xml version="1.0"?>
<robot name="rightHand">
  <link name="wristLarge">
    <visual>
      <geometry>
        <mesh filename="package://inmoov_urdf/meshes/rightHand/WristlargeV4.stl" scale=".001 .001 .001"/>
      </geometry>
      <material name="light_green">
        <color rgba="255 253 208 .35"/>
      </material>
    </visual>
  </link>

  <link name="wristPinky">
    <visual>
      <geometry>
        <mesh filename="package://inmoov_urdf/meshes/rightHand/wristSmallPinky.stl" scale=".001 .001 .001"/>
      </geometry>
      <material name="light_green"/>
      <origin rpy="0 0 -0.90"/>
    </visual>
  </link>

  <link name="wristRing">
    <visual>
      <geometry>
        <mesh filename="package://inmoov_urdf/meshes/rightHand/wristSmallRing.stl" scale=".001 .001 .001"/>
      </geometry>
      <origin rpy="0 0 -0.90" xyz="-0.01 0.0115 -0.0102"/>
      <material name="light_green"/>
    </visual>
  </link>

  <joint name="pinkyKnuck1" type="revolute">
    <limit upper="0.35" lower="0.0" effort="1000.0" velocity="0.5"/>
    <origin rpy="0 0 4.03171057" xyz="0.0195 -0.0105 .0007"/>
    <parent link="wristLarge"/>
    <child link="wristPinky"/>
  </joint>

  <joint name="ringKnuck1" type="revolute">
    <limit upper="0.26" lower="0.0" effort="1000.0" velocity="0.5"/>
    <origin rpy="0 0 4.03171057" xyz="0.005 -0.0105 .0105"/>
    <parent link="wristLarge"/>
    <child link="wristRing"/>
  </joint>
</robot>
