<?xml version="1.0"?>
<robot name="rightHand">

  <link name="wristLarge">
    <visual>
      <geometry>
        <mesh filename="package://inmoov_urdf/meshes/rightHand/WristlargeV4.stl" scale=".001 .001 .001"/>
      </geometry>
      <material name="creme">
        <color rgba="255 253 208 1"/>
      </material>
    </visual>
  </link>

  <!-- Initial wrist joints -->

  <link name="wristPinky">
    <visual>
      <geometry>
        <mesh filename="package://inmoov_urdf/meshes/rightHand/wristSmallPinky.stl" scale=".001 .001 .001"/>
      </geometry>
      <material name="creme"/>
      <origin rpy="0 0 -0.90" xyz="-0.01 0.0115 -0.0102"/>
    </visual>
  </link>

  <joint name="wristPinkyKnuck1" type="revolute">
    <limit upper="0.3" lower="0.0" effort="1000.0" velocity="0.5"/>
    <origin rpy="0 0 4.03171057" xyz="0.005 -0.0105 .0105"/>
    <parent link="wristLarge"/>
    <child link="wristPinky"/>
  </joint>

  <link name="wristRing">
    <visual>
      <geometry>
        <mesh filename="package://inmoov_urdf/meshes/rightHand/wristSmallRing.stl" scale=".001 .001 .001"/>
      </geometry>
      <origin rpy="0 0 -0.90" xyz="-0.01 0.0115 -0.0102"/>
      <material name="creme"/>
    </visual>
  </link>

  <joint name="wristRingKnuck1" type="revolute">
    <limit upper="0.23" lower="0.0" effort="1000.0" velocity="0.5"/>
    <origin rpy="0 0 4.03171057" xyz="0.005 -0.0105 0.0105"/>
    <parent link="wristLarge"/>
    <child link="wristRing"/>
  </joint>

  <!-- Index finger definitions -->

  <link name="indexSeg6">
    <visual>
      <geometry>
        <mesh filename="package://inmoov_urdf/meshes/rightHand/indexSeg6.stl" scale=".001 .001 .001"/>
      </geometry>
      <origin rpy="-1.570796 0 0" xyz="0.01 -0.0207 0.0008"/>
      <material name="creme"/>
    </visual>
  </link>

  <joint name="indexKnuck1" type="revolute">
    <limit upper="-1.74533" lower="0.0" effort="1000.0" velocity="0.5"/>
    <origin rpy="0 0 -0.0875" xyz="-0.0352 -0.0505 0.0107"/>
    <parent link="wristLarge"/>
    <child link="indexSeg6"/>
  </joint>

  <link name="indexSeg5">
    <visual>
      <geometry>
        <mesh filename="package://inmoov_urdf/meshes/rightHand/indexSeg5.stl" scale=".001 .001 .001"/>
      </geometry>
      <origin rpy="1.57 0 0" xyz="-0.0119 -0.0207 0.0012"/>
      <material name="creme"/>
    </visual>
  </link>

  <joint name="indexKnuck1.5" type="fixed">
    <parent link="indexSeg6"/>
    <child link="indexSeg5"/>
  </joint>

  <link name="indexSeg4">
    <visual>
      <geometry>
        <mesh filename="package://inmoov_urdf/meshes/rightHand/indexSeg4.stl" scale=".001 .001 .001"/>
      </geometry>
      <origin rpy="1.57 0 3.14" xyz="-0.0119 -0.0118 -0.0282"/>
      <material name="creme"/>
    </visual>
  </link>

  <joint name="indexKnuck2" type="revolute">
    <limit upper="-1.4" lower="0.0" effort="1000.0" velocity="0.5"/>
    <origin rpy="0 0 0" xyz="-0.0011 -0.0362 0.0007"/>
    <parent link="indexSeg5"/>
    <child link="indexSeg4"/>
  </joint>

  <link name="indexSeg3">
    <visual>
      <geometry>
        <mesh filename="package://inmoov_urdf/meshes/rightHand/indexSeg3.stl" scale=".001 .001 .001"/>
      </geometry>
      <origin rpy="-1.57 0 3.14" xyz="0.0112 -0.0118 0.0274"/>
      <material name="creme"/>
    </visual>
  </link>

  <joint name="indexKnuck2.5" type="fixed">
    <parent link="indexSeg4"/>
    <child link="indexSeg3"/>
  </joint>

  <link name="indexSeg2">
    <visual>
      <geometry>
        <mesh filename="package://inmoov_urdf/meshes/rightHand/indexSeg2.stl" scale=".001 .001 .001"/>
      </geometry>
      <origin rpy="1.57 0 3.14" xyz="-0.0119 -0.01345 0.02695"/>
      <material name="creme"/>
    </visual>
  </link>

  <joint name="indexKnuck3" type="revolute">
    <limit upper="-0.87" lower="0.0" effort="1000.0" velocity="0.5"/>
    <origin rpy="0 0 0" xyz="-0.00035 -0.02408 -0.00042"/>
    <parent link="indexSeg3"/>
    <child link="indexSeg2"/>
  </joint>

  <link name="indexSeg1">
    <visual>
      <geometry>
        <mesh filename="package://inmoov_urdf/meshes/rightHand/indexSeg1.stl" scale=".001 .001 .001"/>
      </geometry>
      <origin rpy="-1.57 0 3.14" xyz="0.01203 -0.0135 -0.02565"/>
      <material name="creme"/>
    </visual>
  </link>

  <joint name="indexKnuck3.5" type="fixed">
    <parent link="indexSeg2"/>
    <child link="indexSeg1"/>
  </joint>

  <!-- Middle finger definitions -->

  <link name="middleSeg6">
    <visual>
      <geometry>
        <mesh filename="package://inmoov_urdf/meshes/rightHand/middleSeg6.stl" scale=".001 .001 .001"/>
      </geometry>
      <origin rpy="-1.570796 0 0" xyz="0.01 -0.02227 0.00073"/>
      <material name="creme"/>
    </visual>
  </link>

  <joint name="middleKnuck1" type="revolute">
    <limit upper="-1.74533" lower="0.0" effort="1000.0" velocity="0.5"/>
    <origin rpy="0 0 0" xyz="-0.0077 -0.0545 0.0107"/>
    <parent link="wristLarge"/>
    <child link="middleSeg6"/>
  </joint>

  <link name="middleSeg5">
    <visual>
      <geometry>
        <mesh filename="package://inmoov_urdf/meshes/rightHand/middleSeg5.stl" scale=".001 .001 .001"/>
      </geometry>
      <origin rpy="1.57 0 0" xyz="-0.0135 -0.02225 0.0016"/>
      <material name="creme"/>
    </visual>
  </link>

  <joint name="middleKnuck1.5" type="fixed">
    <parent link="middleSeg6"/>
    <child link="middleSeg5"/>
  </joint>

  <link name="middleSeg4">
    <visual>
      <geometry>
        <mesh filename="package://inmoov_urdf/meshes/rightHand/middleSeg4.stl" scale=".001 .001 .001"/>
      </geometry>
      <origin rpy="1.57 0 3.14" xyz="-0.0119 -0.01265 -0.03005"/>
      <material name="creme"/>
    </visual>
  </link>

  <joint name="middleKnuck2" type="revolute">
    <limit upper="-1.4" lower="0.0" effort="1000.0" velocity="0.5"/>
    <origin rpy="0 0 0" xyz="-0.00235 -0.0388 0.00085"/>
    <parent link="middleSeg5"/>
    <child link="middleSeg4"/>
  </joint>

  <link name="middleSeg3">
    <visual>
      <geometry>
        <mesh filename="package://inmoov_urdf/meshes/rightHand/middleSeg3.stl" scale=".001 .001 .001"/>
      </geometry>
      <origin rpy="-1.57 0 3.14" xyz="0.0129 -0.01268 0.0292"/>
      <material name="creme"/>
    </visual>
  </link>

  <joint name="middleKnuck2.5" type="fixed">
    <parent link="middleSeg4"/>
    <child link="middleSeg3"/>
  </joint>

<link name="middleSeg2">
    <visual>
      <geometry>
        <mesh filename="package://inmoov_urdf/meshes/rightHand/middleSeg2.stl" scale=".001 .001 .001"/>
      </geometry>
      <origin rpy="1.57 0 3.14" xyz="-0.0119 -0.01433 0.02905"/>
      <material name="creme"/>
    </visual>
  </link>

  <joint name="middleKnuck3" type="revolute">
    <limit upper="-0.87" lower="0.0" effort="1000.0" velocity="0.5"/>
    <origin rpy="0 0 0" xyz="-0.00035 -0.0259 -0.0005"/>
    <parent link="middleSeg3"/>
    <child link="middleSeg2"/>
  </joint>

  <link name="middleSeg1">
    <visual>
      <geometry>
        <mesh filename="package://inmoov_urdf/meshes/rightHand/middleSeg1.stl" scale=".001 .001 .001"/>
      </geometry>
      <origin rpy="-1.57 0 3.14" xyz="0.01375 -0.01435 -0.02775"/>
      <material name="creme"/>
    </visual>
  </link>

  <joint name="middleKnuck3.5" type="fixed">
    <parent link="middleSeg2"/>
    <child link="middleSeg1"/>
  </joint>

  <!-- Ring finger definitions -->

  <link name="ringSeg6">
    <visual>
      <geometry>
        <mesh filename="package://inmoov_urdf/meshes/rightHand/ringSeg6.stl" scale=".001 .001 .001"/>
      </geometry>
      <origin rpy="-1.570796 0 0" xyz="0.01 -0.019845 0.00069"/>
      <material name="creme"/>
    </visual>
  </link>

  <joint name="ringKnuck1" type="revolute">
    <limit upper="-1.74533" lower="0.0" effort="1000.0" velocity="0.5"/>
    <origin rpy="0 0 -3.945" xyz="0.0164 0.035 0.0002"/>
    <parent link="wristRing"/>
    <child link="ringSeg6"/>
  </joint>

  <link name="ringSeg5">
    <visual>
      <geometry>
        <mesh filename="package://inmoov_urdf/meshes/rightHand/ringSeg5.stl" scale=".001 .001 .001"/>
      </geometry>
      <origin rpy="1.57 0 0" xyz="-0.0109 -0.01983 0.00125"/>
      <material name="creme"/>
    </visual>
  </link>

  <joint name="ringKnuck1.5" type="fixed">
    <parent link="ringSeg6"/>
    <child link="ringSeg5"/>
  </joint>

  <link name="ringSeg4">
    <visual>
      <geometry>
        <mesh filename="package://inmoov_urdf/meshes/rightHand/ringSeg4.stl" scale=".001 .001 .001"/>
      </geometry>
      <origin rpy="1.57 0 3.14" xyz="-0.0119 -0.01125 -0.02685"/>
      <material name="creme"/>
    </visual>
  </link>

  <joint name="ringKnuck2" type="revolute">
    <limit upper="-1.4" lower="0.0" effort="1000.0" velocity="0.5"/>
    <origin rpy="0 0 0" xyz="0.00007 -0.0346 0.00085"/>
    <parent link="ringSeg5"/>
    <child link="ringSeg4"/>
  </joint>

  <link name="ringSeg3">
    <visual>
      <geometry>
        <mesh filename="package://inmoov_urdf/meshes/rightHand/ringSeg3.stl" scale=".001 .001 .001"/>
      </geometry>
      <origin rpy="-1.57 0 3.14" xyz="0.01017 -0.01127 0.02607"/>
      <material name="creme"/>
    </visual>
  </link>

  <joint name="ringKnuck2.5" type="fixed">
    <parent link="ringSeg4"/>
    <child link="ringSeg3"/>
  </joint>

<link name="ringSeg2">
    <visual>
      <geometry>
        <mesh filename="package://inmoov_urdf/meshes/rightHand/ringSeg2.stl" scale=".001 .001 .001"/>
      </geometry>
      <origin rpy="1.57 0 3.14" xyz="-0.0119 -0.01279 0.02575"/>
      <material name="creme"/>
    </visual>
  </link>

  <joint name="ringKnuck3" type="revolute">
    <limit upper="-0.87" lower="0.0" effort="1000.0" velocity="0.5"/>
    <origin rpy="0 0 0" xyz="-0.0003 -0.02295 -0.0005"/>
    <parent link="ringSeg3"/>
    <child link="ringSeg2"/>
  </joint>

  <link name="ringSeg1">
    <visual>
      <geometry>
        <mesh filename="package://inmoov_urdf/meshes/rightHand/ringSeg1.stl" scale=".001 .001 .001"/>
      </geometry>
      <origin rpy="-1.57 0 3.14" xyz="0.01094 -0.01281 -0.02455"/>
      <material name="creme"/>
    </visual>
  </link>

  <joint name="ringKnuck3.5" type="fixed">
    <parent link="ringSeg2"/>
    <child link="ringSeg1"/>
  </joint>

</robot>
